### 协程异常处理

协程构建器有两种风格：自动传播异常（启动和参与者）或将它们暴露给用户。当这些构建器用于创建一个根协程，它不是另一个协程的子协程时，前一个构建器将异常视为未捕获的异常，类似于 Java 的 Thread.uncaughtExceptionHandler，而后者则依赖于用户来消费最终异常，例如通过等待或接收。

GlobalScope：

```kotlin
@DelicateCoroutinesApi
fun main() = runBlocking {
    val job = GlobalScope.launch {
        println("Throwing exception from launch")
        throw IndexOutOfBoundsException()
    }
    job.join()
    println("Joined failed job")
    val deferred = GlobalScope.async { // root coroutine with async
        println("Throwing exception from async")
        throw ArithmeticException() // Nothing is printed, relying on user to call await
    }
    try {
        deferred.await()
        println("Unreached")
    } catch (e: ArithmeticException) {
        println("Caught ArithmeticException")
    }
}

>>Throwing exception from launch
>>Exception in thread "DefaultDispatcher-worker-2 @coroutine#2" >>java.lang.IndexOutOfBoundsException
>>Joined failed job
>>Throwing exception from async
>>Caught ArithmeticException
```

#### 协程异常处理器

可以自定义将未捕获的异常打印到控制台的默认行为。根协程上的`CoroutineExceptionHandler`上下文元素可以用作该根协程及其所有子协程的通用`catch`块，其中可能发生自定义异常处理。它类似于`Thread.uncaughtExceptionHandler`。您无法从`CoroutineExceptionHandler`中的异常中回复。调用处理程序时，协程已经完成并出现相应的异常。通常，处理程序用于记录异常、显示某种错误消息、终止或重启应用程序。

在 JVM 上，可以通过`ServiceLoader`注册`CoroutineExceptionHandler`为所有协程重新定义全局异常处理程序。全局异常处理程序类似于`Thread.defaultUncaughtExceptionHandler`，它在没有注册更多特定处理程序时使用。在 Android 上，`uncaughtExceptionPreHandler`被安装为全局协程处理程序。

`CoroutineExceptionHandler`仅在未捕获的异常（未以任何其他方式处理的异常）上调用。特别是，所有子协程将其异常的处理委托给其父协程，父协程也委托给父协程，以此类推到根协程。

```kotlin
val handler = CoroutineExceptionHandler { _, exception ->
    println("CoroutineExceptionHandler got $exception")
}

val job = GlobalScope.launch(handler) { //根协程，运行在GlobalScope
    throw AssertionError()
}

val deferred = GlobalScope.async(handler) { // also root, but async instead of launch
    throw ArithmeticException() // 不会被打印，依赖于用户调用`deferred.await()`
}

joinAll(job, deferred)

>>CoroutineExceptionHandler got java.lang.AssertionError
```

#### 取消和例外

取消与异常密切相关。协程内部使用`CancellationException`进行取消，所有处理程序都会忽略这些异常，因为它们应该仅用作附加调试信息的来源，可以通过`catch`块获取。当使用`Job.cancel`取消协程时，它会终止，但不会取消其父项。

```kotlin
val job = launch {
    val child = launch {
        try {
            delay(Long.MAX_VALUE)
        } finally {
            println("Child is cancelled")
        }
    }
    yield()
    println("Cancelling child")
    child.cancel()
    child.join()
    yield()
    println("Parent is not cancelled")
}
job.join()

>>Cancelling child
>>Child is cancelled
>>Parent is not cancelled
```

如果协程遇到`CancellationException`以外的异常，它会用该异常取消其父进程。此行为不能被覆盖，用于为结构化并发提供稳定的协程层次结构。`CoroutineExceptionHandler`实现不用于子协程。

在这些示例中，`CoroutineExceptionHandler`始终安装在`GlobalScope`创建的协程。将异常处理程序安装到`runBlocking`范围内启动的协程是没有意义的，因为尽管安装了处理程序，但当其子协程以异常完成时，主协程将被取消。

原始异常仅在其所有子级终止时才由父级处理，如下例所示：

```kotlin
val handler = CoroutineExceptionHandler { _, exception ->
    println("CoroutineExceptionHandler got $exception")
}

val job = GlobalScope.launch(handler) {
    launch {
        try {
            delay(Long.MAX_VALUE)
        } finally {
            withContext(NonCancellable) {
                println("Children are cancelled, but exception is not handled until all children terminate")
                delay(100)
                println("The first child finished its non cancellable block")
            }
        }
    }
    launch {
        delay(10)
        println("Second child throws an exception")
        throw ArithmeticException()
    }
}

job.join()

>>Second child throws an exception
>>Children are cancelled, but exception is not handled until all children terminate
>>The first child finished its non cancellable block
>>CoroutineExceptionHandler got java.lang.ArithmeticException
```

#### 异常聚合

当协程的多个子进程因异常而失败时，一般规则时“第一个异常获胜”，因此第一个异常得到处理。在第一个异常之后发生的所有其他异常都作为`suppressed`附加到第一个异常。

```kotlin
fun main() = runBlocking {
    val handler = CoroutineExceptionHandler { _, exception ->
        println("CoroutineExceptionHandler got $exception with suppressed ${exception.suppressed.contentToString()}")
    }
    val job = GlobalScope.launch(handler) {
        launch {
            try {
                delay(Long.MAX_VALUE) // it gets cancelled when another sibling fails with IOException
            } finally {
                throw ArithmeticException() // the second exception
            }
        }
        launch {
            delay(100)
            throw IOException() // the first exception
        }
        delay(Long.MAX_VALUE)
    }
    job.join()
}

>>CoroutineExceptionHandler got java.io.IOException with suppressed [java.lang.ArithmeticException]
```

`Cancellation`异常时透明得，默认情况下时不可见的：

```kotlin
val handler = CoroutineExceptionHandler { _, exception ->
    println("CoroutineExceptionHandler got $exception")
}

val job = GlobalScope.launch(handler) {
    val inner = launch { // 所有这些协程堆栈都将被取消
        launch {
            launch {
                throw IOException() // 原始异常
            }
        }
    }

    try {
        inner.join()
    } catch (e: CancellationException) {
        println("Rethrowing CancellationException with original cause")
        throw e // 重新抛出取消异常，但原始异常（IOException）将得到处理
    }
}

job.join()

>>Rethrowing CancellationException with original cause
>>CoroutineExceptionHandler got java.io.IOException
```

#### Supervision﻿

正如我们之前研究过的，取消时一种双向关系，在整个协程层次结构中传播。我们来看看需要单向取消的情况。

一个很好的示例时在其范围内定义了 UI 组件。如果 UI 的任何子任务失败，并不总是需要取消整个 UI 组件，但是如果 UI 组件被销毁，那么有必要将所有子作业取消，并不再需要他们的结果。

另一个例子是服务器进程，它产生多个子作业，需要监督它们的执行，跟踪它们的失败，并且只重新启动失败的那些。

##### Supervision job

`SupervisorJob`类似与常规的`Job`，唯一的区别是取消仅向下传播。这可以使用以下示例演示：

```kotlin
val supervisor = SupervisorJob()
with(CoroutineScope(coroutineContext + supervisor)) {
    val firstChild = launch(CoroutineExceptionHandler { _, _ -> }) {
        println("1.The first child is failing")
        throw AssertionError("The first child is cancelled")
    }

    val secondChild = launch {
        firstChild.join()
        println("2.The first child is cancelled: ${firstChild.isCancelled}, but the second one is still active")
        try {
            delay(Long.MAX_VALUE)
        } finally {
            println("4.The second child is cancelled because the supervisor was cancelled")
        }
    }
    firstChild.join()
    println("3.Cancelling the supervisor")
    supervisor.cancel()
    secondChild.join()
}

>>1.The first child is failing
>>2.The first child is cancelled: true, but the second one is still active
>>3.Cancelling the supervisor
>>4.The second child is cancelled because the supervisor was cancelled
```

##### Supervision scope

我们可以使用 `supervisionScope` 来代替 `coroutineScope` 进行作用域并发。它仅在一个方向上传播取消，并且仅当它自己失败时才取消其所有子项。它还像 `coroutineScope` 一样在完成之前等待所有子线程。

```kotlin
try {
    supervisorScope {
        val child = launch {
            try {
                println("1.The child is sleeping")
                delay(Long.MAX_VALUE)
            } finally {
                println("3.The child is cancelled")
            }
        }
        yield()
        println("2.Throwing an exception from the scope")
        throw AssertionError()
    }
} catch (e: AssertionError) {
    println("4.Caught an assertion error")
}

>>1.The child is sleeping
>>2.Throwing an exception from the scope
>>3.The child is cancelled
>>4.Caught an assertion error
```

##### `Supervision coroutines`中的异常

普通`Job`和`supervision Job`之间的另一个重要区别是异常处理。每个孩子都应该通过异常处理机制自己处理它的异常。这种差别来自这样一个事实，即孩子的失败不会传播给父母。

```kotlin
val handler = CoroutineExceptionHandler { _, exception ->
    println("3.CoroutineExceptionHandler got $exception")
}
supervisorScope {
    val child = launch(handler) {
        println("2.The child throws an exception")
        throw AssertionError()
    }
    println("1.The scope is completing")
}
println("4.The scope is completed")

>>1.The scope is completing
>>2.The child throws an exception
>>3.CoroutineExceptionHandler got java.lang.AssertionError
>>4.The scope is completed
```

