### 取消和超时

#### 取消协程执行

在长时间运行的应用程序中，您可能需要对后台协程进行颗粒度控制。例如，当用户关闭了启动协程的页面，现在就不需要它的结果，并且需要取消它的操作。`launch`函数返回一个 Job，可用于取消正在运行的协程：

```kotlin
fun main() = runBlocking {
    val job = launch {
        repeat(1000) { i ->
            println("job: I'm sleeping $i ...")
            delay(500)
        }
    }
    delay(1300)
    println("main: I'm tired of waiting!")
    job.cancel()
    job.join()
    println("main: Now I can quit.")
}
```

只有`main`调用了`job.cancel`，我们就看不到其它协程的任何输出，因为它被取消了。还有一个`Job`扩展函数`cancelAndJoin`，它结合了取消和连接调用。

#### 协程的取消是合作的

协程的取消是合作的，协程代码必须协作才能取消。`kotlin.coroutines`中所有挂起函数都是可以取消的。他们检查协程的取消，并在取消时抛出`CancellationException`。但是，如果协程正在计算则不检查取消，并且无法取消它，如下例所示：

```kotlin
val startTime = System.currentTimeMillis()
val job = launch {
    var nextPrintTime = startTime
    var i = 0
    while (i < 5) {//循环计算，只是为了占用cpu
        if (System.currentTimeMillis() >= nextPrintTime) {
            println("job: I'm sleeping ${i++} ...")
            nextPrintTime += 500L
        }
    }
}
delay(1300L)
println("main: I'm tired of waiting!")
job.cancelAndJoin()
println("main: Now I can quit.")
```

运行后发现该程序在取消后继续打印，直到在5次迭代后自行完成。

#### 使计算代码可取消

有两种方法可以使计算代码可取消。第一个使定期调用检查取消的挂起函数。另一个使明确检查取消状态。让我们试试后一种方法。

将上例中的`while(i<5)`替换为`while(isActive)`并重新运行它。

```kotlin
val startTime = System.currentTimeMillis()
val job = launch(Dispatchers.Default) {//必须在另一线程检测协程是否活跃
    var nextPrintTime = startTime
    var i = 0
    while (isActive) {//可取消的计算循环
        if (System.currentTimeMillis() >= nextPrintTime) {
            println("job: I'm sleeping ${i++} ...")
            nextPrintTime += 500L
        }
    }
}
delay(1300L)
println("main: I'm tired of waiting!")
job.cancelAndJoin()
println("main: Now I can quit.")
```

如您所见，现在这个循环被取消了。`isActive`使通过`CoroutineScope`对象在协程内部可用的扩展属性。

#### 使用 finally 关闭资源

可取消的挂起函数会在取消时抛出`CancellationException`，这可以用通常的方式处理。例如，`try{...}finally{...}`表达式和kotlin `use`函数在协程被取消时正常它们的终结操作：

```kotlin
val job = launch {
    try {
        repeat(1000) { i ->
            println("job: I'm sleeping $i ...")
            delay(500L)
        }
    } finally {
        println("job: I'm running finally")
    }
}

delay(1300L) // delay a bit
println("main: I'm tired of waiting!")
job.cancelAndJoin() // cancels the job and waits for its completion
println("main: Now I can quit.")
```

#### 运行不可取消的块

任何在上一个示例的`finally`块中使用挂起函数的尝试都会导致`CancellationException`，因为运行此代码的协程已经被取消。通常，这不是问题，因为所有正常的关闭操作（关闭文件、取消作业或关闭任何类型的通信通道）通常都是非阻塞的，并且不涉及任何挂起功能。但是在极少数情况下，当需要在取消的协程中挂起时，您可以使用`withContext`函数和`NonCancellable`上下文将相应的代码包装在`withContext(NonCancellable){...}`中，如下例所示：

```kotlin
val job = launch {
    try {
        repeat(1000) { i ->
            println("job: I'm sleeping $i ...")
            delay(500L)
        }
    } finally {
        withContext(NonCancellable) {
            println("job: I'm running finally")
            delay(1000L)
            println("job: And I've just delayed for 1 sec because I'm non-cancellable")
        }

    }
}

delay(1300L) // delay a bit
println("main: I'm tired of waiting!")
job.cancelAndJoin() // cancels the job and waits for its completion
println("main: Now I can quit.")
```

#### 超时

取消协程最常用的原因是因为它的执行时间超过了某个时间段。虽然您可以手动跟踪，在延迟之后在一个单独的协程中持有被跟踪协程的引用，以取消协程。但有一个随时可用的`withTimeout`函数可以做到这一点：

```kotlin
withTimeout(1300L) {
    repeat(1000) { i ->
        println("I'm sleeping $i ...")
        delay(500L)
    }
}
```

`withTimeout`抛出的`TimeoutCancellationException`是`CancallationException`的子类。我们之前没有在控制台上看到它的堆栈跟踪。那是因为在取消的协程中，`CancellationException`被认为是协程完成的正常原因。然而，在这个例子中，我们的`main`函数中使用了`withTimeout`。

`withTimeout`还有一个函数`withTimeoutNull`，在超时时返回`null`而不是异常：

```kotlin
val result = withTimeoutOrNull(1300L) {
    repeat(1000) { i ->
        println("I'm sleeping $i ...")
        delay(500L)
    }
    "Done" // will get cancelled before it produces this result
}
println("Result is $result")
```

#### 异步超时与资源

`withTimeout`中的超时事件与其块中运行的代码是异步的，并且可能随时发生，甚至在从超时块内部返回之前。如果在块内打开或获取某些需要在块外关闭或释放的资源，请一定要释放资源：

```kotlin
var acquired = 0

class Resource {
    init { acquired++ } // Acquire the resource
    fun close() { acquired-- } // Release the resource
}

fun main() {
    runBlocking {
        repeat(100_000) { // Launch 100K coroutines
            launch { 
                val resource = withTimeout(60) { // Timeout of 60 ms
                    delay(50) // Delay for 50 ms
                    Resource() // Acquire a resource and return it from withTimeout block     
                }
                resource.close() // Release the resource
            }
        }
    }
    // Outside of runBlocking all coroutines have completed
    println(acquired) // Print the number of resources still acquired
}
```

如果运行上面的代码，你会看到结果并不总是0，要解决这个问题，您可以在变量中存储对资源的引用，而不是从`withTimeout`块中返回它。

```kotlin
runBlocking {
    repeat(100_000) { // Launch 100K coroutines
        launch { 
            var resource: Resource? = null // Not acquired yet
            try {
                withTimeout(60) { // Timeout of 60 ms
                    delay(50) // Delay for 50 ms
                    resource = Resource() // Store a resource to the variable if acquired      
                }
                // We can do something else with the resource here
            } finally {  
                resource?.close() // Release the resource if it was acquired
            }
        }
    }
}
// Outside of runBlocking all coroutines have completed
println(acquired) // Print the number of resources still acquired
```

此时`acquired`的值总是为0，资源不泄露。